<?xml version='1.0'?>
<robot name="car_robot">
	
	<material name="green">
		<color rgba="0 1 0.0 1"/>
	</material>

	<material name="white">
		<color rgba="1 1 1 1"/>
	</material>

	<material name="black">
		<color rgba="0.1 0.1 0.1 1"/>
	</material>
	
	<!--dummy link-->
	<link name="base_link"/>

	<!--chassis link-->
	<link name="chassis-link">
		<visual>
			<origin xyz="0 0 0" rpy="0 0 0" />
			<geometry>
				<box size="0.2 0.12 .05" />
			</geometry>
			<material name="red">
				<color rgba="1.0 0 0 1"/>
			</material>		
		</visual>
		<collision>
			<origin xyz="0 0 0" rpy="0 0 0" />
			<geometry>
				<box size="0.2 0.12 .01" />
			</geometry>
		</collision>
		<inertial>
			<mass value="0.4" />
			<inertia ixx="0.00048333" iyy="0.0013367" izz="0.0018133"
			ixy="0" ixz="0" iyz="0"/>
		</inertial>
	</link>

	<!-- ========== FACE LINKS ========== -->

	<link name="eye-left-link">
		<visual>
			<origin xyz="0 0 0" rpy="0 0 0" />
			<geometry><sphere radius="0.009" /></geometry>
			<material name="white" />
		</visual>
	</link>

	<link name="eye-right-link">
		<visual>
			<origin xyz="0 0 0" rpy="0 0 0" />
			<geometry><sphere radius="0.009" /></geometry>
			<material name="white" />
		</visual>
	</link>

	<link name="pupil-left-link">
		<visual>
			<origin xyz="0 0 0" rpy="0 0 0" />
			<geometry><sphere radius="0.005" /></geometry>
			<material name="black" />
		</visual>
	</link>

	<link name="pupil-right-link">
		<visual>
			<origin xyz="0 0 0" rpy="0 0 0" />
			<geometry><sphere radius="0.005" /></geometry>
			<material name="black" />
		</visual>
	</link>

	<link name="eyebrow-left-link">
		<visual>
			<origin xyz="0 0 0" rpy="0 0 0.4" />
			<geometry><box size="0.003 0.018 0.003" /></geometry>
			<material name="black" />
		</visual>
	</link>

	<link name="eyebrow-right-link">
		<visual>
			<origin xyz="0 0 0" rpy="0 0 -0.4" />
			<geometry><box size="0.003 0.018 0.003" /></geometry>
			<material name="black" />
		</visual>
	</link>

	<link name="smile-link">
	<visual>
		<origin xyz="0 0 0" rpy="0 0 0" />
		<geometry>
		<mesh filename="package://car_robot/meshes/smile.stl" scale="1 1 1"/>
		</geometry>
		<material name="black" />
	</visual>
	</link>

	<!-- ========== WHEEL LINKS ========== -->

	<link name="front-right-wheel-link">
		<visual>
			<origin xyz="0 0 0" rpy="1.57079 0 0" />
			<geometry>
				<cylinder radius ="0.05" length="0.01" />
			</geometry>
			<material name="green" />
		</visual>
		<collision>
			<origin xyz="0 0 0" rpy="1.57079 0 0" />
			<geometry>
				<cylinder radius ="0.05" length="0.01" />
			</geometry>
		</collision>
		<inertial>
			<origin xyz="0 0 0" rpy="1.57079 0 0" />
			<mass value="0.2" />
			<inertia ixx="0.00004667" iyy="0.00004667" izz="0.00009"
			ixy="0" ixz="0" iyz="0"/>
		</inertial>
	</link>
	
	<link name="front-left-wheel-link">
		<visual>
			<origin xyz="0 0 0" rpy="1.57079 0 0" />
			<geometry>
				<cylinder radius ="0.05" length="0.01" />
			</geometry>
			<material name="green" />
		</visual>
		<collision>
			<origin xyz="0 0 0" rpy="1.57079 0 0" />
			<geometry>
				<cylinder radius ="0.05" length="0.01" />
			</geometry>
		</collision>
		<inertial>
			<origin xyz="0 0 0" rpy="1.57079 0 0" />
			<mass value="0.2" />
			<inertia ixx="0.00004667" iyy="0.00004667" izz="0.00009"
			ixy="0" ixz="0" iyz="0"/>
		</inertial>
	</link>
	
	<link name="rear-right-wheel-link">
		<visual>
			<origin xyz="0 0 0" rpy="1.57079 0 0" />
			<geometry>
				<cylinder radius ="0.05" length="0.01" />
			</geometry>
			<material name="green" />
		</visual>
		<collision>
			<origin xyz="0 0 0" rpy="1.57079 0 0" />
			<geometry>
				<cylinder radius ="0.05" length="0.01" />
			</geometry>
		</collision>
		<inertial>
			<origin xyz="0 0 0" rpy="1.57079 0 0" />
			<mass value="0.2" />
			<inertia ixx="0.00004667" iyy="0.00004667" izz="0.00009"
			ixy="0" ixz="0" iyz="0"/>
		</inertial>
	</link>
	
	<link name="rear-left-wheel-link">
		<visual>
			<origin xyz="0 0 0" rpy="1.57079 0 0" />
			<geometry>
				<cylinder radius ="0.05" length="0.01" />
			</geometry>
			<material name="green" />
		</visual>
		<collision>
			<origin xyz="0 0 0" rpy="1.57079 0 0" />
			<geometry>
				<cylinder radius ="0.05" length="0.01" />
			</geometry>
		</collision>
		<inertial>
			<origin xyz="0 0 0" rpy="1.57079 0 0" />
			<mass value="0.2" />
			<inertia ixx="0.00004667" iyy="0.00004667" izz="0.00009"
			ixy="0" ixz="0" iyz="0"/>
		</inertial>
	</link>
	
	<!-- ========== CHASSIS JOINT ========== -->

	<joint name="joint-base-chassis" type="fixed">
		<parent link="base_link"/>
		<child link="chassis-link"/>
		<origin xyz="0 0 0.03" rpy="0 0 0" />
	</joint>

	<!-- ========== FACE JOINTS ========== -->

	<joint name="joint-eye-left" type="fixed">
		<parent link="chassis-link"/>
		<child link="eye-left-link"/>
		<origin xyz="0.102 0.028 0.005" rpy="0 0 0" />
	</joint>

	<joint name="joint-eye-right" type="fixed">
		<parent link="chassis-link"/>
		<child link="eye-right-link"/>
		<origin xyz="0.102 -0.028 0.005" rpy="0 0 0" />
	</joint>

	<joint name="joint-pupil-left" type="fixed">
		<parent link="eye-left-link"/>
		<child link="pupil-left-link"/>
		<origin xyz="0.006 -0.003 0.004" rpy="0 0 0" />
	</joint>

	<joint name="joint-pupil-right" type="fixed">
		<parent link="eye-right-link"/>
		<child link="pupil-right-link"/>
		<origin xyz="0.006 0.003 0.004" rpy="0 0 0" />
	</joint>

	<joint name="joint-eyebrow-left" type="fixed">
		<parent link="chassis-link"/>
		<child link="eyebrow-left-link"/>
		<origin xyz="0.102 0.028 0.022" rpy="0 0 0" />
	</joint>

	<joint name="joint-eyebrow-right" type="fixed">
		<parent link="chassis-link"/>
		<child link="eyebrow-right-link"/>
		<origin xyz="0.102 -0.028 0.022" rpy="0 0 0" />
	</joint>

<joint name="joint-smile" type="fixed">
	<parent link="chassis-link"/>
	<child link="smile-link"/>
	<origin xyz="0.101 0.0 0.0" rpy="0 0 0" />
	</joint>


	<!-- ========== WHEEL JOINTS ========== -->
	
	<joint name="joint-chassis-front-right-wheel" type="continuous">
		<parent link="chassis-link"/>
		<child link="front-right-wheel-link"/>
		<origin xyz="0.06 0.065 0" rpy="0 0 0" />
		<axis xyz="0 1 0" />
	</joint>
	
	<joint name="joint-chassis-front-left-wheel" type="continuous">
		<parent link="chassis-link"/>
		<child link="front-left-wheel-link"/>
		<origin xyz="0.06 -0.065 0" rpy="0 0 0" />
		<axis xyz="0 1 0" />
	</joint>
	
	<joint name="joint-chassis-rear-right-wheel" type="continuous">
		<parent link="chassis-link"/>
		<child link="rear-right-wheel-link"/>
		<origin xyz="-0.06 0.065 0" rpy="0 0 0" />
		<axis xyz="0 1 0" />
	</joint>
	
	<joint name="joint-chassis-rear-left-wheel" type="continuous">
		<parent link="chassis-link"/>
		<child link="rear-left-wheel-link"/>
		<origin xyz="-0.06 -0.065 0" rpy="0 0 0" />
		<axis xyz="0 1 0" />
	</joint>
	
</robot>